<?xml version="1.0"?>
<!-- <robot name="ets_vii" xmlns:xacro="http://ros.org/wiki/xacro"> -->
<robot name="ets_vii">
  <link name="base_link">
    <visual>
      <origin rpy="0 0 0" xyz="0 0 0" />
      <geometry>
        <box size="2 2 2" />
      </geometry>
    </visual>
  </link>

  <link name="link_1">
    <visual>
      <origin rpy="0 0 0" xyz="0.025 0 0.25" />
      <geometry>
        <box size="0.25 0.3 0.5" />
      </geometry>
    </visual>
  </link>

  <joint name="joint1" type="revolute">
    <axis xyz="0 0 1"/>
    <limit effort="1000.0" lower="-3.0" upper="3.0" velocity="0.5"/>
    <parent link="base_link" />
    <child link="link_1" />
    <origin xyz="-0.79 -0.29 1" />
  </joint>

  <link name="link_2">
    <visual>
      <origin rpy="0 0 0" xyz="0.125 0 0.435" />
      <geometry>
        <box size="0.25 0.2 1.17" />
      </geometry>
    </visual>
  </link>

  <joint name="joint2" type="revolute">
    <axis xyz="1 0 0"/>
    <limit effort="1000.0" lower="-3.0" upper="3.0" velocity="0.5"/>
    <parent link="link_1" />
    <child link="link_2" />
    <origin xyz="0.15 0 0.35" />
  </joint>
  
   <link name="link_3">
    <visual>
      <origin rpy="0 0 0" xyz="0.025 0 0.350" />
      <geometry>
        <box size="0.25 0.2 0.86" />
      </geometry>
    </visual>
  </link>

  <joint name="joint3" type="revolute">
    <axis xyz="-1 0 0"/>
    <limit effort="1000.0" lower="-3.0" upper="3.0" velocity="0.5"/>
    <parent link="link_2" />
    <child link="link_3" />
    <origin xyz="-0.125 0 0.87" />
  </joint>

  <link name="link_4">
    <visual>
      <origin rpy="0 0 0" xyz="0 0 0.127" />
      <geometry>
        <cylinder radius="0.15" length="0.427"/>
      </geometry>
    </visual>
  </link>

   <joint name="joint4" type="revolute">
    <axis xyz="1 0 0"/>
    <limit effort="1000.0" lower="-3.0" upper="3.0" velocity="0.5"/>
    <parent link="link_3" />
    <child link="link_4" />
    <origin xyz="-0.262 0 0.63" />
  </joint>

  <link name="link_5">
    <visual>
      <origin rpy="0 1.57079 0" xyz="0 0 0.127" />
      <geometry>
        <cylinder radius="0.15" length="0.25"/>
      </geometry>
    </visual>
  </link>

   <joint name="joint5" type="revolute">
    <axis xyz="0 0 1"/>
    <limit effort="1000.0" lower="-3.0" upper="3.0" velocity="0.5"/>
    <parent link="link_4" />
    <child link="link_5" />
    <origin xyz="0 0 0.277" />
  </joint>

  <link name="link_6">
    <visual>
      <origin rpy="0 1.57079 0" xyz="0.141 0 0" />
      <geometry>
        <cylinder radius="0.1" length="0.282"/>
      </geometry>
    </visual>
  </link>

   <joint name="joint6" type="revolute">
    <axis xyz="1 0 0"/>
    <limit effort="1000.0" lower="-3.0" upper="3.0" velocity="0.5"/>
    <parent link="link_5" />
    <child link="link_6" />
    <origin xyz="0.125 0 0.15" rpy="0 0 0" />
  </joint>


</robot>